<robot name = "robot">
    <link name="Left_Body">
        <inertial>
            <origin xyz="-1.5 0 0" rpy="0 0 0"/>
            <mass value="1" />
            <inertia ixx="100" ixy="0" ixz="0" iyy="100" iyz="0" izz="100" />
        </inertial>
        <visual>
            <origin xyz="-1.5 0 0" rpy="0 0 0"/>
            <geometry>
                <box size="3 1 1" />
            </geometry>
            <material name="Cyan">
                <color rgba="0 1.0 1.0 1.0"/>
            </material>
        </visual>
        <collision>
            <origin xyz="-1.5 0 0" rpy="0 0 0"/>
            <geometry>
                <box size="3 1 1" />
            </geometry>
        </collision>
    </link>
    <link name="Right_Body">
        <inertial>
            <origin xyz="1.5 0 0" rpy="0 0 0"/>
            <mass value="1" />
            <inertia ixx="100" ixy="0" ixz="0" iyy="100" iyz="0" izz="100" />
        </inertial>
        <visual>
            <origin xyz="1.5 0 0" rpy="0 0 0"/>
            <geometry>
                <box size="3 1 1" />
            </geometry>
            <material name="Cyan">
                <color rgba="0 1.0 1.0 1.0"/>
            </material>
        </visual>
        <collision>
            <origin xyz="1.5 0 0" rpy="0 0 0"/>
            <geometry>
                <box size="3 1 1" />
            </geometry>
        </collision>
    </link>
    <joint name="Left_Right_Joint" type="revolute">
       <parent link="Left_Body"/>
       <child  link="Right_Body"/>
       <origin rpy="0 0 0" xyz="0 0 0" />
       <axis xyz="0 1 0"/>
       <limit effort="0.0" lower="-3.14159" upper="3.14159" velocity="0.0"/>
    </joint>
</robot>